[0;33m--- esp-idf-monitor 1.3.4 on /dev/cu.usbserial-01A178B2 115200 ---[0m
[0;33m--- Quit: Ctrl+] | Menu: Ctrl+T | Help: Ctrl+T followed by Ctrl+H ---[0m
[0;33m0x40080400: _init at ??:?
[0m
[1;31mNone[0m
[0;33mWaiting for the device to reconnect[0m[0;33m[0m
[0;33m0x40080400: _init at ??:?
[0m
[1;31mNone[0m
[0;33mWaiting for the device to reconnect[0m[0;33m.[0m[0;33m.[0m[0;33m[0m
[0;33m0x40080400: _init at ??:?
[0m
[1;31mNone[0m
[0;33mWaiting for the device to reconnect[0m[0;33m.[0m[0;33m.[0m[0;33m.[0m[0;33m.[0m[0;33m.[0mException in thread Thread-2 (_run_outer):
Traceback (most recent call last):
  File "/Users/marcin/.espressif/python_env/idf5.3_py3.10_env/lib/python3.10/site-packages/serial/serialposix.py", line 575, in read
    buf = os.read(self.fd, size - len(read))
OSError: [Errno 6] Device not configured

During handling of the above exception, another exception occurred:

Traceback (most recent call last):
  File "/Users/marcin/.espressif/python_env/idf5.3_py3.10_env/lib/python3.10/site-packages/esp_idf_monitor/base/serial_reader.py", line 59, in run
    data = self.serial.read(self.serial.in_waiting or 1)
  File "/Users/marcin/.espressif/python_env/idf5.3_py3.10_env/lib/python3.10/site-packages/serial/serialposix.py", line 581, in read
    raise SerialException('read failed: {}'.format(e))
serial.serialutil.SerialException: read failed: [Errno 6] Device not configured

During handling of the above exception, another exception occurred:

Traceback (most recent call last):
  File "/Users/marcin/.pyenv/versions/3.10.13/lib/python3.10/threading.py", line 1016, in _bootstrap_inner
    self.run()
  File "/Users/marcin/.pyenv/versions/3.10.13/lib/python3.10/threading.py", line 953, in run
    self._target(*self._args, **self._kwargs)
  File "/Users/marcin/.espressif/python_env/idf5.3_py3.10_env/lib/python3.10/site-packages/esp_idf_monitor/base/stoppable_thread.py", line 47, in _run_outer
    self.run()
  File "/Users/marcin/.espressif/python_env/idf5.3_py3.10_env/lib/python3.10/site-packages/esp_idf_monitor/base/serial_reader.py", line 70, in run
    self.open_serial(self.reset)
  File "/Users/marcin/.espressif/python_env/idf5.3_py3.10_env/lib/python3.10/site-packages/esp_idf_monitor/base/serial_reader.py", line 86, in open_serial
    self.serial.open()
  File "/Users/marcin/.espressif/python_env/idf5.3_py3.10_env/lib/python3.10/site-packages/serial/serialposix.py", line 332, in open
    self._reconfigure_port(force_update=True)
  File "/Users/marcin/.espressif/python_env/idf5.3_py3.10_env/lib/python3.10/site-packages/serial/serialposix.py", line 517, in _reconfigure_port
    termios.tcsetattr(
termios.error: (6, 'Device not configured')
[0m
